Workbook

Sheet Sheet1
A1: post_id | B1: subreddit | C1: raw_text | D1: search_keyword | E1: gpt_rs_judgment | F1: gpt_confidence | G1: gpt_rationale | H1: gpt_indicators | I1: gpt_signals | J1: gpt_domain_topic
A2: P-001 | B2: r/Anxiety | C2: Hey guys.. this is something I’ve really needed to talk about and need reassurance/ help with This started for me about a month ago. Everytime I drive I’m worried I hit something or someone and left the scene. I’ve spent hours googling “ would I know if I hit a person?” “Would I know if I hit a mailbox?” Every single time I hit a “pot hole” I think it is a person. What if I didn’t see them? What if it was a small child? It scares me so much. I spend so much time circling back and checking my dash cams just to make sure.. that I didn’t. Everytime I’ve looked I never have. But I still can’t shake the feeling..” What if I did?” . I always ask my passengers and they say I drove fine.. I’m worried. And I’m scared. It’s gotten so bad that I hardly drive anymore. Does anyone else suffer with this? Really need reassurance here. | D2: (re)assure me/ need (re)assurance | E2: Yes | F2: 5 | G2: The post centers on a feared harm outcome (having hit someone/something and fled) and explicitly seeks reassurance that this did not happen. Multiple strong RS indicators are present: direct certainty demand ("need reassurance"), redundancy through repeated checking/googling and prior reassurance from dash cams/passengers, plus persistence/escalation via recurring what-if spirals. | H2: ["certainty_demand", "redundancy", "persistence/escalation", "affect_urgency"] | I2: ["\"need reassurance/ help with\"", "\"I’ve spent hours googling\"", "\"circling back and checking my dash cams just to make sure\"", "\"Everytime I’ve looked I never have. But I still can’t shake the feeling\"", "\"I always ask my passengers and they say I drove fine\""] | J2: General Threat > external_safety
A3: P-002 | B3: r/Anxiety | C3: is vaping making my anxiety worse? i started vaping over a year ago, and i seriously am starting to think it’s the reason my anxiety has gotten so bad. it’s not the cause of it, my anxiety’s been around for ages, but it definitely has been worse since vaping. has anyone else had kind of a similar experience? or did anyone else find that their anxiety calmed down after quitting? becuase i really just need to know and i wanna try really hard to quit. i kinda more just need reassurance. any tips are useful! | D3: (re)assure me/ need (re)assurance | E3: No | F3: 5 | G3: The post is primarily seeking shared experience and practical input about whether quitting vaping helped anxiety, in order to support a behavior change, rather than asking for certainty that a feared outcome will not occur. Although the user says they 'need reassurance,' this functions more as encouragement around quitting and experience-sharing, which fits genuine information/advice seeking rather than reassurance-seeking. | H3: [] | I3: ["'has anyone else had kind of a similar experience? or did anyone else find that their anxiety calmed down after quitting?'", "'i wanna try really hard to quit'", "'any tips are useful!'"] | J3: General Threat > health
A4: P-003 | B4: r/Anxiety | C4: i’m so scared of war...so guys basically i’ve been thinking a lot about war and i’m so scared. i live in america and i’ve been having panic attacks im so fucking scared. i don’t wanna lose everyone close to me. i can’t go to therapy and i keep trying to enjoy life but it fucks me up and every time i enjoy something i think “what if we get into war” i know it sounds stupid and childish but i’m so fucking scared. i need reassurance i’m gonna be okay and no war will happen. can some of you guys like show some things that prove it won’t happen any time soon? i’m so genuinely terrified that i can barely get out of bed i try to sleep off the thoughts but they just give me horrific nightmares. please can anyone just show me things that prove i’ll be okay and that war won’t happen any time soon? | D4: (re)assure me/ need (re)assurance | E4: Yes | F4: 5 | G4: The post centers on a clear external safety threat (fear of war) and explicitly solicits certainty that the feared outcome will not occur. It contains strong certainty demand ("i need reassurance," "prove it won’t happen") plus affect-driven urgency and repeated what-if fixation, making reassurance-seeking the dominant function. | H4: ["certainty_demand", "persistence/escalation", "affect_urgency"] | I4: ["\"i need reassurance i’m gonna be okay and no war will happen\"", "\"show some things that prove it won’t happen any time soon\"", "\"every time i enjoy something i think ‘what if we get into war’\""] | J4: General Threat > external_safety
A5: P-004 | B5: r/Anxiety | C5: Please help I’m in a crisis Im sure other people may be feeling like this, and maybe I’m overthinking or overreacting but I really need help… the whole Iran, Isreal USA stuff is genuinely really really scaring me. I’m crying and having panic attacks over it.. and I need help. I need reassurance, good sources that say we are not heading for ww3…just….something that everything will be okay, and I hate to sound selfish but I need to know the uk will be okay. My family is here….i know that sounds awful and selfish but i really need help… I need tips and advice and reassurance I can’t cope | D5: (re)assure me/ need (re)assurance | E5: Yes | F5: 5 | G5: The post centers on an external safety threat (fear of war/WW3 affecting the UK) and explicitly asks others to provide certainty that the feared outcome will not occur. It contains strong certainty demand ("I need reassurance," "good sources that say we are not heading for ww3," "something that everything will be okay") plus clear affect-driven urgency ("I’m crying and having panic attacks," "I can’t cope"). | H5: ["certainty_demand", "affect_urgency"] | I5: ["\"I need reassurance\"", "\"good sources that say we are not heading for ww3\"", "\"something that everything will be okay\"", "\"I need to know the uk will be okay\""] | J5: General Threat > external_safety
A6: P-005 | B6: r/Anxiety | C6: i need Reassurance Hi guys so about a month ago i put it inside a girl and thought i came but know i didn’t, and i was scared she was pregnant but she has had her period twice, meaning she’s not. i still get really really bad anxiety everyday and overthink it thinking what if she is, how do i get rid of these constant thoughts all the time and the fear even though i know it’s going to be alright? | D6: (re)assure me/ need (re)assurance | E6: No | F6: 3 | G6: The post centers on a pregnancy threat and mentions ongoing anxiety despite reassuring evidence ('she has had her period twice'), but the dominant request is for help coping with intrusive thoughts ('how do i get rid of these constant thoughts') rather than directly asking others to confirm she is not pregnant. This makes it borderline, with redundancy present in content but the post functioning more as coping-seeking than active reassurance-seeking. | H6: [] | I6: ["'how do i get rid of these constant thoughts all the time and the fear'", "'she has had her period twice, meaning she’s not'"] | J6: General Threat > health
A7: P-006 | B7: r/Anxiety | C7: I’m having severe anxiety since last night due to me thinking I saw something but nothing was really there it was late at night. But it caused me to think that I’m seeing things and I’m going to go crazy or become schizophrenic. I try distracting myself but I can’t stop obsessing over it . What if im already acting crazy and don’t even realize it? I need reassurance please help!! | D7: (re)assure me/ need (re)assurance | E7: Yes | F7: 5 | G7: The post centers on a perceived mental health threat ('going to go crazy or become schizophrenic') and explicitly asks others for reassurance to rule out that feared outcome. It also shows persistence/escalation through obsessive rumination ('I can’t stop obsessing over it,' 'What if im already acting crazy') and strong affect-driven urgency. | H7: ["certainty_demand", "persistence/escalation", "affect_urgency"] | I7: ["'I need reassurance please help!!'", "'I’m going to go crazy or become schizophrenic'", "'I can’t stop obsessing over it'", "'What if im already acting crazy and don’t even realize it?'"] | J7: General Threat > health
A8: P-007 | B8: r/Anxiety | C8: I’m travelling to London next week for an event I’m really excited for, but seeing headlines and Google saying London is at “Substantial risk” for a terrorist attack has made me extremely anxious. The venue is in central London, so I keep thinking worst case scenario, researching what I’d do if something happened, and even considering getting a refund. My mum is telling me I’m making myself more scared by focusing on it so much. I’m trying to distract myself with more positive things to take my mind off of it and trying to keep my brain rational, but it’s super hard. This may sound silly, I think I just need reassurance that I'll be okay | D8: (re)assure me/ need (re)assurance | E8: Yes | F8: 5 | G8: The post centers on a perceived external safety threat (terrorist attack) and explicitly asks for reassurance that the feared outcome will not happen. It also shows persistence through repeated worst-case thinking and researching despite the mother's input that the user is over-focusing on it. | H8: ["certainty_demand", "redundancy", "persistence/escalation", "affect_urgency"] | I8: ["\"I think I just need reassurance that I'll be okay\"", "\"I keep thinking worst case scenario\"", "\"researching what I’d do if something happened\"", "\"My mum is telling me I’m making myself more scared by focusing on it so much\""] | J8: General Threat > external_safety
A9: P-008 | B9: r/Anxiety | C9: why isn't it getting better. my anxiety is driving me crazy. i know life can be anything you want because its all based on perspective but its like anxiety wont leave me no matter what. its like i can never do things myself and i always need reassurance from other people. why cant i accept that some people wont like me and its not a me problem and i dont have to take everything personally. | D9: (re)assure me/ need (re)assurance | E9: No | F9: 5 | G9: This is primarily meta-level reflection on the user's anxiety and reassurance-seeking pattern rather than an attempt to obtain reassurance in the post itself. The user does not solicit confirmation that a specific feared outcome is false; instead they describe their struggle and ask why they rely on reassurance. | H9: [] | I9: ["\"i always need reassurance from other people\"", "The post describes their pattern and distress rather than asking readers to confirm that people do not dislike them."] | J9: Social/Self-worth > social_relational
A10: P-009 | B10: r/Anxiety | C10: I feel like no matter how much people assure me that they like me or they're my friend I don't truly believe it. If I'm not anxious that they're going to leave me and stop being my friend then im anxious that they're secretly not really my friend and they just keep me around for some other reason. I understand at a level I'm being ridiculous, but I still can't shake this feeling. I know my self esteem is not so great and that doesn't help. I also know that I can be pretty shy and introverted as well. I just wish I could shake these feelings. Is this social anxiety? | D10: (re)assure me/ need (re)assurance | E10: No | F10: 5 | G10: This is primarily a meta-level description of the user's pattern of doubting reassurance and asking for a possible label ('Is this social anxiety?'), which fits the exclusion for describing one's own RS pattern rather than enacting reassurance-seeking in the post itself. Although the post mentions fears about friends secretly not liking them, it does not solicit confirmation that a specific feared outcome is false from the reader. | H10: [] | I10: ["'no matter how much people assure me... I don't truly believe it' describes an ongoing pattern", "'Is this social anxiety?' asks for a diagnostic label rather than reassurance that friends really like them"] | J10: Social/Self-worth > social_relational
A11: P-010 | B11: r/Anxiety | C11: My BF and I had an argument last week that turned nasty. We weren't going to break up but he said a few hurtful things. I have very bad anxiety and no matter how many times he tells me everything is okay and we're all good, I can't shake the feeling that its not (i know its my anxiety). I can't stop needing reassurance constantly that everything is okay and its driving him crazy but its so hard to stop. Help? | D11: (re)assure me/ need (re)assurance | E11: No | F11: 5 | G11: This post describes the user's reassurance-seeking pattern and asks for help managing it, rather than soliciting confirmation that the relationship is definitely okay in this post. It fits the exclusion for meta-level reflection on one's own RS behavior ('I can't stop needing reassurance constantly') rather than enacting reassurance-seeking toward the reader. | H11: [] | I11: ["'I can't stop needing reassurance constantly'", "'its driving him crazy but its so hard to stop'", "'Help?' indicates advice/coping support rather than asking readers to confirm the feared outcome is false"] | J11: Social/Self-worth > social_relational
A12: P-011 | B12: r/SocialAnxiety | C12: need reassurance that nobody is judging me while I’m washing dishes. I know it sounds super ridiculous but lately I can feel my social anxiety getting worse due to the fact I’m too scared to even do the dishes with the blinds open… again ): I really don’t want my social anxiety to get worse like it did last summer and this was a first sign of it. The kitchen window is in front of a very busy street and lately my neighbors right across have their garage door wide open because I am assuming they are working on a car. And it feels so difficult doing the dishes knowing they are there or thinking that someone could be looking right at me and judging me in any way or maybe that they notice little things about myself that I do like how shaky I am and judging me go that. I just need some reassurance that they actually don’t care at all. thank you lmao | D12: (re)assure me/ need (re)assurance | E12: Yes | F12: 5 | G12: The post centers on a social threat of being watched and judged, and it explicitly solicits affirmation to relieve that fear: "I just need some reassurance that they actually don’t care at all." This is a clear certainty demand rather than open-ended advice-seeking, with distress about worsening social anxiety supporting the RS reading. | H12: ["certainty_demand", "affect_urgency"] | I12: ["\"I just need some reassurance that they actually don’t care at all\"", "fear that neighbors are \"looking right at me and judging me\"", "\"I really don’t want my social anxiety to get worse\""] | J12: Social/Self-worth > social_relational
A13: P-012 | B13: r/SocialAnxiety | C13: Anyone else believe in mind readers. Like im sitting in my room right now watching a youtube video and i think the guy is cute but i feel like i cant fully let myself relax and just enjoy this video and looking at him because theres a mind reader with telepathic powers just reading my mind and not even making fun of me or cringing at me hes just there watching and listening to me Like even writing this out i can just imagine him reading my mind as i type this and just being a presence in the back of my mind just watching and listening to every thought in my head and of course im a grown adult so i know thats impossible theres so such thing as mind reading but theres still a apart of me that just truly believes theres a professor x out there just inside my head just listening to me and judging me Can any scientists in the chat please reassure me thats theres no logical way someone can read minds please im a sciencey guy i love biology and evolution and all that jazz but i just cant shake this feeling | D13: (re)assure me/ need (re)assurance | E13: Yes | F13: 5 | G13: The post centers on a perceived threat of being mentally observed/judged and explicitly asks others to confirm that this feared possibility is impossible. It shows certainty demand ("please reassure me"), redundancy/dismissed self-knowledge ("i know thats impossible... but i just cant shake this feeling"), and persistence of the fear despite contrary reasoning. | H13: ["certainty_demand", "redundancy", "persistence/escalation", "affect_urgency"] | I13: ["\"please reassure me thats theres no logical way someone can read minds\"", "\"i know thats impossible theres so such thing as mind reading but theres still a apart of me that just truly believes\"", "\"i just cant shake this feeling\""] | J13: General Threat > external_safety
... A251: P-250 | B251: r/Anxiety | C251: Burnout Hi everyone! Lately I have been experiencing the greatest burnout I have ever had in my life. I am a Sophomore in college and I really struggle with making it to my classes due to my anxiety and having zero, I mean ZERO motivation. I envy my friends who are able to just go to class consistently and not miss any. I can usually make it a week without missing class but then the burnout hits me and I miss class the next week. It has gotten to the point where my attendance in my classes have been very bad (at my college they are very strict on attendance). But literally no matter how hard I try I can’t even explain it I like PHYSICALLY cannot get myself to go. When I come home I wish I could stay there forever and sit in my bed and do nothing for the rest of my life. I just need reassurance that I am not the only one feeling this way right now. Or maybe I am😂 | D251: (re)assure me/ need (re)assurance | E251: No | F251: 4 | G251: The post primarily describes burnout and asks for shared experience/normalization ('I am not the only one feeling this way') rather than seeking certainty that a specific feared outcome will not occur. Although the word 'reassurance' is used, the dominant function is emotional support around burnout, not reassurance-seeking about a concrete threat. | H251: [] | I251: ["'I just need reassurance that I am not the only one feeling this way right now' indicates normalizing/shared-experience support rather than ruling out a feared outcome", "The post mainly vents about burnout, anxiety, and attendance struggles without asking others to confirm a specific danger or mistake is not happening"] | J251: Decision Making > career_academic
A252: P-251 | C252: I really, really need someone (preferably a group of people maybe) to talk to me and assure me that I'm not losing my mind. Please. I feel excessively anxious today. And I know what's triggering it. I feel as though I'm losing my sanity. I know this is one of the heavy symptoms of anxiety, but my brain is deciding to make my body feel anxious regardless. I sometimes (when it's really quiet and I'm really tired) hear conversations going on in my head. Of course, this is leading me to think I'm developing Schizophrenia.. It's making me extremely uneasy. I'll go more into detail on the "conversation" thing. It's, like I said above, when the room is very quiet and I'm really tired. Most of the time when I'm sleeping/falling asleep. I don't hear the voices as though they were in the room. It's like when one consciously imagines a conversation in their head. My brain, however, does it all on its own. It's also always familiar voices (family/relatives). I never hear any long sentences. It's usually just a few words. I also only hear one person at a time, as though the person were talking to someone else. Somebody please reply to this. | D252: (re)assure me/ need (re)assurance | E252: Yes | F252: 3 | G252: The post centers on a feared health threat (developing schizophrenia/losing sanity) and explicitly solicits reassurance from others to rule that out. It shows strong certainty demand through direct requests for assurance and some redundancy because the user already notes an anxiety-based explanation ('I know this is one of the heavy symptoms of anxiety') but still seeks confirmation. | H252: ["certainty_demand", "redundancy", "affect_urgency"] | I252: ["\"need someone ... to assure me that I'm not losing my mind\"", "\"Of course, this is leading me to think I'm developing Schizophrenia\"", "\"I know this is one of the heavy symptoms of anxiety\"", "\"Somebody please reply to this\""] | J252: General Threat > health
A253: P-252 | B253: r/Anxiety | C253: I have really bad anxiety about my health and major health events, and have had an intense fear of strokes after my teacher passed away from one . I am an active 17 year old, and have no other health conditions besides asthma (it was worse when I was younger, I hardly ever have breathing problems from it now). Can anyone else relate to this, and would someone please assure me that my risk for one is low? Logically I know that but I still get nervous about it | D253: (re)assure me/ need (re)assurance | E253: Yes | F253: 3 | G253: The post centers on a health threat (fear of having a stroke) and explicitly asks others to provide safety confirmation: 'would someone please assure me that my risk for one is low.' It also shows redundancy because the user already states 'Logically I know that' but still seeks reassurance to relieve ongoing anxiety. | H253: ["certainty_demand", "redundancy", "affect_urgency"] | I253: ["'would someone please assure me that my risk for one is low'", "'Logically I know that but I still get nervous about it'", "'really bad anxiety about my health'"] | J253: General Threat > health
A254: P-253 | B254: r/Anxiety | C254: I am anxious to ask a question. I need assurance...! I am a senior who's not attending their grad ceremony due to low self esteem and social anxiety issues. The thought of the announcers calling my name and I'm not there, has been making me a bit anxious. I have already told the school counselor that I wasn't going and the only thing they said to me was that I don't have to go if I don't want to. I was expecting to hear more like idk, maybe the process of officially crossing myself off the attendance the list (if that's a thing?). Overall, I just want to avoid my name being called. It gives me a bit of anxiety for some reason. Idk if they would take attendance of those at the ceremony. I want to ask the counselor in order to clear this doubt off my mind but I'm kind of embarrassed to ask. Would it be a dumb question? Do they still call your name at the ceremony regardless if you're there or not? I need to hear some assurance because I have 24 hours left to ask! | D254: (re)assure me/ need (re)assurance | E254: Yes | F254: 4 | G254: The post centers on a feared social outcome (their name being called despite not attending) and explicitly seeks reassurance to reduce that anxiety rather than neutrally gathering information. It shows certainty demand ("I need assurance," "I need to hear some assurance") plus redundancy because the user already asked the counselor but remains unsettled and seeks further confirmation. | H254: ["certainty_demand", "redundancy", "affect_urgency"] | I254: ["\"I need assurance...!\"", "\"I have already told the school counselor...\"", "\"Would it be a dumb question? Do they still call your name... regardless if you're there or not?\"", "\"I need to hear some assurance because I have 24 hours left to ask!\""] | J254: Social/Self-worth > social_relational
A255: P-254 | B255: r/Anxiety | C255: Spiraling about what might happen! Hi! So, I’m a legal immigrant and I’ve lived in this country for almost 20 years now, but lately, with everything that’s been happening within the US, I’ve been so worried and it’s never been as bad as it is right now. I look at everything I have right now and feel like I won’t have it for long and that everything will be taken away from me and I’ll be sent back to a country that I don’t have anything in. In fact, I moved here when I was a kid and can barely even speak that language so everything I have is here in this country. Anyways, I’m rambling. I have lately been in a state of fear for myself, my family and a lot of my friends who are also immigrants. I know that everything will most likely be okay for me, but that doesn’t seem to truly assure me. I’m so afraid. | D255: (re)assure me/ need (re)assurance | E255: No | F255: 4 | G255: The post centers on a clear external safety threat, but it does not actually solicit confirmation or ask others to rule out the feared outcome; it mainly describes fear and distress. Although the user notes prior self-reassurance ('I know that everything will most likely be okay for me'), the dominant function is venting rather than seeking reassurance from readers. | H255: [] | I255: ["'I’m so worried and it’s never been as bad as it is right now'", "'I know that everything will most likely be okay for me, but that doesn’t seem to truly assure me'", "No direct question or request for others to confirm safety"] | J255: General Threat > external_safety
A256: P-255 | B256: r/Anxiety | C256: recently i’ve been hyper focused on my eye movements and how quickly they are can someone either assure me this is normal or explain why my eyes move to quickly my brain cant seem to keep up while i’m anxious.does this happen to anyone else, like your eyes are just flashes of images? only is bad when i focus on it but its hard not to. suffering from a bit of dpdr and really visual is the only problem. i have bvd so glasses should fix some symptoms :( | D256: (re)assure me/ need (re)assurance | E256: Yes | F256: 4 | G256: The post centers on a health-related threat about abnormal eye movements and explicitly asks others to 'assure me this is normal,' which is a clear certainty demand. The mention of anxiety, hyperfocus, and existing BVD/glasses suggests the user already has some explanatory context yet is still seeking confirmation that the feared implication is not serious. | H256: ["certainty_demand", "redundancy", "affect_urgency"] | I256: ["'can someone either assure me this is normal'", "'recently i’ve been hyper focused on my eye movements'", "'i have bvd so glasses should fix some symptoms'"] | J256: General Threat > health
A257: P-256 | B257: r/SocialAnxiety | C257: Need Advice ! So i want to start studying economics this winter, but now i heared from someone who already studies it, that i will have to give many talks. Since i am a bit shy and have social anxiety, giving talks is a hell for me.I am very scared just by thinking about it. My Question is: Should i still do it and just face giving talks ? ( even though i know i will do them badly and it will bother me the whole time.. ) or schould i chose another degree program with less talks and more theoretical, which surely exists in the field of economics. ( this would assure me a more relaxed time, and i wouldnt be stressed all this time through) Sry my english isn't the best :s | D257: (re)assure me/ need (re)assurance | E257: No | F257: 4 | G257: The post is primarily genuine decision-making advice-seeking about choosing a degree program based on the practical demands of presentations and the user's social anxiety. It presents two options and asks for guidance about tradeoffs rather than seeking certainty that a feared outcome will not occur or discounting prior reassurance. | H257: [] | I257: ["\"Should i still do it and just face giving talks ? ... or schould i chose another degree program with less talks\"", "The post asks about how to choose between options rather than asking others to confirm that a feared outcome is false."] | J257: Decision Making > career_academic
A258: P-257 | B258: r/HealthAnxiety | C258: Anxiety symptoms What are everyone’s worst symptoms that they suffer with from anxiety? Mine are: -dizziness (lightheaded, feels like the floors moving/dropping beneath me, unsteady, feels like I will pass out, etc.) -feeling really hot and getting hot flushes -rushes of adrenaline through my whole body -tingling hands -feeling like I’m not actually here (dissociation) -spaced out feeling -‘floaty’ feeling -body parts feel distorted at times -feeling extremely tired, heavy eyelids, like I just need to close my eyes -Breathlessness Probably so many more that I have forgotten about haha! Hope this maybe gives some people some reassurance. I often feel like my symptoms are ‘too severe’ to be JUST anxiety. Dizziness is the worst for me.The physical symptoms are SO real but they are just a feeling! The less we attention we give them (easier said than done, I know) , the more likely they will go away. | D258: (re)assure me/ need (re)assurance | E258: No | F258: 5 | G258: The post primarily shares the user's own anxiety symptoms and invites others to discuss theirs, which functions as shared experience/community discussion rather than soliciting certainty that a specific feared outcome will not occur. Although the user mentions feeling their symptoms are sometimes 'too severe' to be 'just anxiety,' they do not ask others to rule out a threat or validate a feared interpretation; instead they offer encouragement and coping framing. | H258: [] | I258: ["'What are everyone’s worst symptoms that they suffer with from anxiety?'", "'Hope this maybe gives some people some reassurance'", "'The physical symptoms are SO real but they are just a feeling!'"] | J258: General Threat > health
A259: P-258 | B259: r/HealthAnxiety | C259: ALS? So I've dealt with hypochondria my entire life (since I was about five or six), and I'm sure this is just my anxiety messing with me, but as per usual, I'm freaking out. Out of the blue, I am *convinced* I have ALS. My leg muscles have been twitching and my carpal tunnel has been acting up, so sometimes my hand will spasm and it's freaking me out more than usual. If I do have any symptoms, chances are it's just psychosomatic, but I can't get my mind off of it. I'm sure it's just my brain acting up, but I *need* someone to tell me I'm okay. I just need some sort of reassurance. | D259: (re)assure me/ need (re)assurance | E259: Yes | F259: 3 | G259: The post centers on a health threat (fear of having ALS) and explicitly solicits reassurance to rule out that feared outcome. It shows certainty demand through direct requests for affirmation and redundancy through acknowledging prior self-knowledge that this is likely anxiety/psychosomatic while still seeking confirmation. | H259: ["certainty_demand", "redundancy", "affect_urgency"] | I259: ["\"I am convinced I have ALS\"", "\"I'm sure this is just my anxiety messing with me\"", "\"I need someone to tell me I'm okay\"", "\"I just need some sort of reassurance\""] | J259: General Threat > health
A260: P-259 | B260: r/Anxiety | C260: I am in community college and this term I am most definitely about to fail two of my classes. I got my schedules all fucked up between my two jobs, and had no chance to make it to class (i have to work to pay for school, but can't make it to school. Oh the irony) Anyways, I'm sitting here stressed as all hell. Will this ruin my chances at transferring to a university? Is my college life over? My GPA is not horrible, and will remain relatively high, but will the F's on my transcript make it so I can't get into a university even if I retake the classes and get the credits? Also please don;t come in on your high horses and call me lazy and a bad student. I do well in school generally but this term I had to work conflicting schedules to be able to pay for school next term. I know had I been more proactive I may have avoided this. But I need reassurance that I can recover from this | D260: (re)assure me/ need (re)assurance | E260: Yes | F260: 5 | G260: The post centers on a feared negative outcome about academic future ('ruin my chances at transferring,' 'college life over') and explicitly asks for reassurance that this setback is recoverable. The dominant function is not open-ended transfer advice but certainty-seeking that failing two classes will not permanently damage the user's prospects. | H260: ["certainty_demand", "affect_urgency"] | I260: ["'Will this ruin my chances at transferring to a university? Is my college life over?'", "'But I need reassurance that I can recover from this'"] | J260: Decision Making > career_academic
A261: P-260 | B261: r/Anxiety | C261: Character AI Is character AIA good substitute for therapy for between me going to therapy. I have a real therapist but sometimes I just really need reassurance and I would rather just have it by something that isn't really alive so it can't come back to bite me . But it seems to give sometimes really bad advice or completel be miss read the situation and make me spiral. It's kind of the only thing I have because I'm kind of driving myself insane by posting on here | D261: (re)assure me/ need (re)assurance | E261: No | F261: 4 | G261: The post is primarily meta-level reflection about the user's reassurance-seeking pattern and asking whether Character AI is a useful coping substitute between therapy sessions, rather than directly soliciting certainty that a specific feared outcome will not occur. Although the user mentions needing reassurance and spiraling, the dominant function is advice-seeking about managing their behavior/tool use. | H261: [] | I261: ["\"Is character AIA good substitute for therapy\"", "\"I have a real therapist but sometimes I just really need reassurance\"", "\"It's kind of the only thing I have because I'm kind of driving myself insane by posting on here\""] | J261: General Threat > health
A262: P-261 | B262: r/Anxiety | C262: Health anxiety I deal with horrible and sometimes painful symptoms on the daily for five years now. I’ve been told that I might have chronic tension headaches for example. I’m aware that anxiety can affect your physically but I’m such a hypochondriac that I can’t help but to think that something is seriously wrong with me all the time. I’ve been to doctors/neurologists/eye doctors and even got an MRI done which says that I am fine but I can’t help but to worry because I still deal with these things everyday as well as other areas on my body such as tingling , crawling sensastions... anyways I just need reassurance constantly (please don’t scare me too much lol) pls give me advice | D262: (re)assure me/ need (re)assurance | E262: Yes | F262: 3 | G262: The post centers on a health threat ('something is seriously wrong with me') and explicitly solicits reassurance despite extensive prior medical reassurance, including doctors and an MRI saying they are fine. It shows strong redundancy and certainty demand, with ongoing worry that persists despite negative evaluations. | H262: ["certainty_demand", "redundancy", "persistence/escalation", "affect_urgency"] | I262: ["'I just need reassurance constantly'", "'I’ve been to doctors/neurologists/eye doctors and even got an MRI done which says that I am fine'", "'I can’t help but to think that something is seriously wrong with me all the time'"] | J262: General Threat > health
A263: P-262 | B263: r/Anxiety | C263: Scared to go to sleep cause I'm too tired??? I'm sleep deprived so I'm feeling kinda weird. My anxiety is telling me to be scared to go to sleep cause of this feeling. Assure me I'm ok please 😞 | D263: (re)assure me/ need (re)assurance | E263: Yes | F263: 5 | G263: The post centers on a perceived health/safety threat tied to bodily sensations and explicitly asks others to confirm safety: 'Assure me I'm ok please.' This is a textbook certainty demand aimed at relieving anxiety rather than seeking new information. | H263: ["certainty_demand", "affect_urgency"] | I263: ["'I'm sleep deprived so I'm feeling kinda weird'", "'My anxiety is telling me to be scared to go to sleep'", "'Assure me I'm ok please'"] | J263: General Threat > health
A264: P-263 | B264: r/Anxiety | C264: I have anxiety from this situation I went by the sink a few minutes ago and noticed two cups with leftover orange juice from 1/2 days ago that I remember being there, but I seriously remember emptying them yesterday or the day before and now when I looked at the sink they looked the exact same? Did I imagine that I did it? Seriously freaking out. Anyway my anxiety is spiraling and I need reassurance. My anxiety is going to: I somehow jumped to a different reality or dimension. But I need to know this is common, right? | D264: (re)assure me/ need (re)assurance | E264: Yes | F264: 5 | G264: The post centers on a perceived threat of having 'jumped to a different reality or dimension' and explicitly asks others to relieve that fear with confirmation that the experience is common. It contains a direct certainty demand ('I need reassurance,' 'this is common, right?') plus affect-driven urgency ('Seriously freaking out,' 'my anxiety is spiraling'). | H264: ["certainty_demand", "affect_urgency"] | I264: ["'I need reassurance'", "'But I need to know this is common, right?'", "'Seriously freaking out'", "'my anxiety is spiraling'"] | J264: General Threat > external_safety
... A1795: P-1794 | B1795: r/makemychoice | C1795: Should I keep talking to my ex or not? My ex and broke up a couple days ago. She wanted to be friends and see if we could go back to dating. I don’t know if I want to stay or go. On one hand she does things that make me feel so much pain and on the other hand I just feel like I can’t live without her. Even though we argue a lot I don’t know what to do. Part of me thinks staying in contact is only going to hurt me more, but then I start wondering if cutting her off means I’m giving up too soon. I would really appreciate if someone just made this decision for me. | D1795: should I | E1795: Yes | F1795: 5 | G1795: The post centers on a feared wrong relationship choice and explicitly asks others to decide for the user, which functions as external validation/permission rather than open-ended deliberation. It is somewhat borderline because there is no clear prior reassurance or repetitive escalation, but the dominant function is to offload uncertainty about making the wrong decision. | H1795: ["judgment_validation", "certainty_demand"] | I1795: ["\"I don’t know if I want to stay or go\"", "\"I would really appreciate if someone just made this decision for me\""] | J1795: Decision Making > personal_lifechoice
A1796: P-1795 | B1796: r/makemychoice | C1796: Work at Google or work at Apple? I currently work at Google, in engineering. I've been there 5 years. I'm burned out on my current job and have been looking around over the past year or so. Now I have two job offers, one internal and one at Apple. They are super similar jobs. Very similar tasks and projects and even technology. Same location (not California), same pay. The Apple offer includes lots of equity so I don't have to feel so dumb about losing all that Google stock. I guess it comes down to culture but what does that even mean during Covid? Also all those Google perks are meaningless right now and it feels like normal office life might never really come back. I've done pro and con lists and all kinds of different decision tools and asked everyone I know for advice, but it's hard when the choices are so much alike. Flip a coin? Flip an iPhone or a Pixel? 😂 | E1796: Yes | F1796: 3 | G1796: The post centers on a decision-making threat about choosing the wrong job, and the user reports having already used multiple decision tools and asked many people for advice but still seeks more input. This suggests redundancy and some persistence, though it remains borderline because the tone is relatively light and could also be read as ordinary deliberation between genuinely similar options. | H1796: ["redundancy", "persistence/escalation"] | I1796: ["\"I've done pro and con lists and all kinds of different decision tools and asked everyone I know for advice\"", "\"it's hard when the choices are so much alike\"", "\"Work at Google or work at Apple?\""] | J1796: Decision Making > career_academic
A1797: P-1796 | B1797: r/makemychoice | C1797: Should I buy a house where I am, or move across the country? My sister lives out west and I live east. All our friends and family are east, minus my sister and her husband. However, they live in the mountains, somewhere I have always wanted to live. I visit my sister multiple times a year. We currently have the financial means to either move cross country and rent, or buy a house where we are, but not both. I have been wrestling with this decision for years. Like, literally, years. I have talked this to death with my friends and family and cannot figure out what to do. Help, please. | D1797: should I | E1797: Yes | F1797: 4 | G1797: The post centers on a feared wrong life choice and shows reassurance-seeking through redundancy and judgment validation: the user has 'wrestl[ed] with this decision for years' and 'talked this to death with friends and family' but still asks others to help determine the safe/right choice. This is not framed as balanced tradeoff-gathering so much as repeated solicitation to relieve unresolved doubt about making a major move decision. | H1797: ["redundancy", "judgment_validation", "persistence/escalation"] | I1797: ["'I have been wrestling with this decision for years'", "'I have talked this to death with my friends and family'", "'cannot figure out what to do. Help, please.'"] | J1797: Decision Making > personal_lifechoice
A1798: P-1797 | B1798: r/makemychoice | C1798: Finally blocked my ex It was a tough decision I have ever made. Looking back even thought I have my mental health problem but I still make time for him, find someone interesting in the rs/convo, make a future plan to meet up and all, I am really proud of myself it makes me realises what I can do for love and also I understand that I can’t change someone when they choose to stay in the same place. It’s so sad and funny he told me that it’s the ldr problem and he wants someone can be present and around him when he can’t be present to himself and his life, also why do you have to blame it’s the ldr problem when we have phone to call and video call? And also we can plan a time to meet too?? It’s never a problem it’s just that he is choosing his family & his friends over him and his partner. It’s his lost right? But I am happy that I finally blocked & delete him as I just want to move on in my life and priorities myself again. | D1798: right? | E1798: Yes | F1798: 4 | G1798: The post centers on a social/relational threat of rejection and asks for validation of the poster's interpretation and decision via 'It's his lost right?' rather than purely venting. However, it is mixed with breakup processing and self-affirmation, so the reassurance-seeking signal is present but borderline. | H1798: ["judgment_validation"] | I1798: ["\"It’s his lost right?\"", "one-sided framing about why the ex was at fault and the blocking was justified"] | J1798: Decision Making > personal_lifechoice
A1799: P-1798 | B1799: r/makemychoice | C1799: Surprise Trip to Egypt? My friend is a known travel lover and is always jet setting off to a new location all the time. Recently for my birthday, they surprised me with an all expenses paid trip to Egypt - Cairo. They've got a nice itinerary planned to visit the piramids and all this wonderful stuff. The problem im facing is that we are set to travel next month while a lot of uncertainty is building up over there. Would i be awful to suggest we delay the trip or am i reading too much into the news? Please help me make my decision. Wwyd? | D1799: am I overthinking | E1799: Yes | F1799: 4 | G1799: The post centers on a perceived external safety threat ('uncertainty is building up over there') and asks others to validate the user's judgment about whether postponing is warranted ('Would i be awful to suggest we delay the trip or am i reading too much into the news?'). This is somewhat borderline because it also resembles genuine advice-seeking, but the dominant function leans toward seeking confirmation that their concern is justified and not an overreaction. | H1799: ["judgment_validation"] | I1799: ["'a lot of uncertainty is building up over there'", "'Would i be awful to suggest we delay the trip or am i reading too much into the news?'", "'Please help me make my decision. Wwyd?'"] | J1799: General Threat > external_safety
A1800: P-1799 | B1800: r/makemychoice | C1800: Should I move back home to help my family or stay and build my own life? I’m 26, living in a different city for work, and finally starting to feel like I’m building something of my own, career growth, a solid group of friends, and a sense of independence I’ve never had before. But recently, my mom’s health has been declining and my younger siblings (14 and 11) are still at home. My dad works long hours, and they’ve quietly hinted that it would really help if I came back, even temporarily. I feel guilty for even hesitating, but part of me is afraid I’ll lose everything I’ve worked for if I go. I keep going over the same reasons in my head and still can’t shake the feeling that whichever choice I make will mean I failed someone. Is it selfish to want to stay? Or would I regret not being there for them when they need me most? This decision is eating me up. | D1800: should I | E1800: Yes | F1800: 4 | G1800: The post centers on a feared wrong choice with moral and relational consequences, and the user seeks external validation that staying would not make them selfish or a failure. It shows judgment validation ("Is it selfish to want to stay?") and some persistence/escalation ("I keep going over the same reasons in my head"), though it is somewhat mixed with genuine deliberation. | H1800: ["judgment_validation", "persistence/escalation", "affect_urgency"] | I1800: ["\"Is it selfish to want to stay?\"", "\"I keep going over the same reasons in my head\"", "\"whichever choice I make will mean I failed someone\""] | J1800: Decision Making > career_academic
A1801: P-1800 | B1801: r/makemychoice | C1801: Someone please make this decision for me, I’ve officially tapped out I’ve been going back and forth on this for way too long, and now I feel like my brain is a browser with 87 tabs open and not a single one is responding. I don’t even trust myself to pick anymore. I’ve rationalized both sides, changed my mind 10+ times, and now I’m mentally exhausted. So here I am, throwing myself at the mercy of Reddit. I think I know what I’m leaning toward, but every time I settle on it I immediately start thinking it’s going to be the wrong call and I’ll regret it later. I’m not going to say what the options are just yet I want to see how people think without influence. I just need someone (anyone!) to say “do this” so I can finally sleep at night. | D1801: please just tell me | E1801: Yes | F1801: 4 | G1801: The post centers on distress about making the wrong choice and explicitly seeks external confirmation/permission to decide for them rather than open-ended reasoning. It shows judgment validation (wanting others to ratify the choice), persistence/escalation ("changed my mind 10+ times"), and affect-driven urgency ("so I can finally sleep at night"). | H1801: ["judgment_validation", "persistence/escalation", "affect_urgency"] | I1801: ["\"Someone please make this decision for me\"", "\"changed my mind 10+ times\"", "\"I just need someone (anyone!) to say 'do this' so I can finally sleep at night\""] | J1801: Decision Making > personal_lifechoice
A1802: P-1801 | B1802: r/makemychoice | C1802: should i call out of work should i call out of work tomorrow morning? i work with kids at an after school program, today was rough and i ended up losing my voice from how many shenanigans we had with the kids. i came home to being stressed out over college homework i had to do, and my new car breaking down again and not having the money to fix it - this rest of the week until i have to fix it, i cannot drive my car and have to catch rides. ive only called out sick maybe three or four times, for genuinely being sick and i’ve worked there a year. i’d probably call out and say that my voice is still not back properly and hurts and i’m exhausted (but really i just need a mental health day). i guess im just worried because i called out about a month ago. i can push myself through, im just so upset and tired and feel i can’t make the right decision. i keep telling myself one day isn’t a big deal, but then i feel like i’m being dramatic or irresponsible for even considering it. | D1802: should I | E1802: Yes | F1802: 4 | G1802: The post centers on a decision-making threat about whether calling out is the wrong choice, and the user explicitly seeks external validation because they 'feel i can’t make the right decision.' Although there is some genuine practical context, the dominant function is judgment validation rather than open-ended problem-solving. | H1802: ["redundancy", "judgment_validation"] | I1802: ["'should i call out of work tomorrow morning?'", "'i feel i can’t make the right decision'", "'i keep telling myself one day isn’t a big deal, but then i feel like i’m being dramatic or irresponsible'"] | J1802: Decision Making > career_academic
A1803: P-1802 | B1803: r/makemychoice | C1803: Did i make the right choice? I have been with a guy for 7 months now. He’s all a girl can dream of, he constantly goes out of his way to make me happy. We were okay until i started getting doubts about him and if i want to continue in this relationship. He always tells me i have an avoidant attachment style and whenever things get serious i bail and seek my independence, that is very true and its a pattern i have been noticing in myself. I broke up with him 2 days ago and I’m regretting it. And I honestly dont know if i really dont wanna be with him anymore or if its my avoidant part making the decision. I dont think i will ever meet a guy like him. Part of me feels like I ruined something good for no real reason, but then I also don’t know if going back would just be me panicking because I’m alone now. And i dont know what to do. | D1803: am I right?/ is this wrong choice/decision | E1803: Yes | F1803: 3 | G1803: The post centers on a feared wrong-choice outcome in a relationship and asks for confirmation about whether breaking up was a mistake, which fits judgment validation. It is somewhat borderline because the user also seems genuinely confused and asks what to do, but the dominant function is seeking external validation that the decision was or was not the right one. | H1803: ["judgment_validation"] | I1803: ["\"Did i make the right choice?\"", "\"I’m regretting it\"", "\"I honestly dont know if i really dont wanna be with him anymore or if its my avoidant part making the decision\""] | J1803: Decision Making > personal_lifechoice
A1804: P-1803 | B1804: r/makemychoice | C1804: Is It Time to Let Go of the Woman I Still Love? I recently posted a photo of my ex on my WhatsApp status. Her sister saw it and informed her. Since my ex had blocked me on all platforms, I couldn’t reach her directly,but today, she called me. She told me to delete all her pictures and asked me never to post her again. I still love her and deep down, I’ve been hoping we might reconnect. But after that call, I felt emotionally drained and finally realized it might be time to let go and move on with my life. The truth is, I’m the one who hurt her and gave her reasons to walk away. Now I’m wondering,am I making the right decision by choosing to move on, even though I still care deeply about her? | D1804: am I right?/ is this wrong choice/decision | E1804: Yes | F1804: 4 | G1804: The post centers on a social/attachment threat of losing the relationship for good, and the user asks others to validate a judgment they are already leaning toward: 'it might be time to let go and move on.' This is not mainly open-ended advice-seeking; the dominant function is seeking confirmation that moving on is the right/safe decision in the face of emotional doubt. | H1804: ["judgment_validation"] | I1804: ["'it might be time to let go and move on with my life'", "'am I making the right decision by choosing to move on'", "ongoing hope that 'we might reconnect' despite her blocking him and telling him not to post her"] | J1804: Decision Making > personal_lifechoice
A1805: P-1804 | B1805: r/makemychoice | C1805: Should i accept a friends with benefits deal? We're old friends and she recently confessed that she doesn't really like anyone at the moment and wants to experiment with someone she hasn't got feelings for. I originally accepted but now I'm having doubts. I'm basically in the same boat as her but my main concerns are 1. It's against everything I usually preach for 2. If something happens it will also affect our mutual friends.(On the contrary we can experiment with everything basically because theres no risk of pregnancy) I know too well that my personal problems are a very big factor in my decision but I cant help myself. Please prove me wrong so i can deny it and move on without getting into unnecessary shit. | D1805: should I | E1805: Yes | F1805: 4 | G1805: The post centers on a feared negative outcome from a personal choice (getting into 'unnecessary shit' and social fallout) and explicitly asks others to invalidate the poster's current doubts: 'Please prove me wrong so i can deny it.' This is more than open-ended deliberation because the user signals a leaning and seeks external confirmation to neutralize self-doubt, though it remains somewhat mixed with genuine decision-making. | H1805: ["judgment_validation"] | I1805: ["'Please prove me wrong so i can deny it and move on'", "'I originally accepted but now I'm having doubts'", "concerns about affecting 'our mutual friends' and getting into 'unnecessary shit'"] | J1805: Decision Making > personal_lifechoice
A1806: P-1805 | B1806: r/makemychoice | C1806: 23 going from engineering to union electrical work Hey everyone, Im 23 and Ive been part time drudging my way through an electrical engineering degree. Ive been at it for 3 years now, at this point Im exhausted. Since Ive been working and paying for my classes, I have no student debt which is nice. I still probably have another 2 or 3 years at the rate im going. Since this degree has taken me so long, I feel like a complete loser. I no longer enjoy this major anymore. Im thinking im just going to try to join the IBEW. I dont want to be a broke student going into my mid-20s, get kicked off my parents health insurance, and be unable to find a job when I graduate. From what I can see online, the job market for engineers looks trash right now anyways (for new grads). Maybe being an electrician is the better pathway forward for me, and I still have an associates degree in EE for the time being. I keep looking up the same posts about engineering vs trades, but it never really settles anything. I think I want someone to just tell me I’m not throwing my life away by leaving the degree. Am I making a mistake? I need feedback on my thought process because my parents are useless and give me zero guidence. | D1806: making a mistake | E1806: Yes | F1806: 5 | G1806: The post centers on a decision-making threat about leaving the degree and seeks confirmation that this choice is not disastrous rather than open-ended tradeoff analysis. It shows persistence/redundancy through repeated checking ("I keep looking up the same posts") and a clear certainty/judgment-validation request ("tell me I’m not throwing my life away," "Am I making a mistake?"). | H1806: ["certainty_demand", "redundancy", "judgment_validation", "persistence/escalation"] | I1806: ["\"I keep looking up the same posts about engineering vs trades, but it never really settles anything\"", "\"I think I want someone to just tell me I’m not throwing my life away by leaving the degree\"", "\"Am I making a mistake?\""] | J1806: Decision Making > career_academic
A1807: P-1806 | B1807: r/makemychoice | C1807: Marketing to Dental Role I’ve been in marketing for about 5 years. I’ve never loved it but it’s always paid well and it’s been fully remote. Recently my team has gotten a lot more toxic and I’ve been searching for a new role for months. Ive been very unhappy and felt really miserable in the desk job type role in general. I’ve always considered going back to school as well because I’ve thought I’d enjoy a more clinical role instead of a desk/office type job. I recently applied for a dental assistant role and was offered the job on the spot. They will do on the job training and the idea would be that I would then start the process to go back to school for dental hygiene. I’ve looked into dental hygiene a lot and know what pre reqs id need to take this summer to get started. Am I making a mistake leaving a well paying remote job for a lower paying dental assistant role and counting on going back to school? I’m just waiting on the offer letter and trying to not freak out! | D1807: making a mistake | E1807: Yes | F1807: 4 | G1807: The post centers on a feared negative outcome of making the wrong career choice and explicitly asks for validation about that judgment: "Am I making a mistake leaving a well paying remote job...". Although it also contains practical decision context, the dominant function leans toward seeking confirmation that the choice is not a mistake rather than open-ended tradeoff analysis. | H1807: ["judgment_validation", "affect_urgency"] | I1807: ["\"Am I making a mistake leaving a well paying remote job...\"", "\"trying to not freak out\"", "already researched the dental hygiene path and prerequisites"] | J1807: Decision Making > career_academic
...

Sheet Summary
A1: gpt_domain_topic (gpt_rs_judgment = Yes) — count by gpt_confidence
A2: gpt_domain_topic | B2: 2 | C2: 3 | D2: 4 | E2: 5 | F2: Total
A3: Decision Making > career_academic | B3: =COUNTIFS(Sheet1!$E:$E,"Yes",Sheet1!$J:$J,$A3,Sheet1!$F:$F,B$2) -> 3 | C3: =COUNTIFS(Sheet1!$E:$E,"Yes",Sheet1!$J:$J,$A3,Sheet1!$F:$F,C$2) -> 32 | D3: =COUNTIFS(Sheet1!$E:$E,"Yes",Sheet1!$J:$J,$A3,Sheet1!$F:$F,D$2) -> 37 | E3: =COUNTIFS(Sheet1!$E:$E,"Yes",Sheet1!$J:$J,$A3,Sheet1!$F:$F,E$2) -> 15 | F3: =SUM(B3:E3) -> 87
A4: Decision Making > personal_lifechoice | B4: =COUNTIFS(Sheet1!$E:$E,"Yes",Sheet1!$J:$J,$A4,Sheet1!$F:$F,B$2) -> 5 | C4: =COUNTIFS(Sheet1!$E:$E,"Yes",Sheet1!$J:$J,$A4,Sheet1!$F:$F,C$2) -> 33 | D4: =COUNTIFS(Sheet1!$E:$E,"Yes",Sheet1!$J:$J,$A4,Sheet1!$F:$F,D$2) -> 38 | E4: =COUNTIFS(Sheet1!$E:$E,"Yes",Sheet1!$J:$J,$A4,Sheet1!$F:$F,E$2) -> 18 | F4: =SUM(B4:E4) -> 94
A5: General Threat > external_safety | B5: =COUNTIFS(Sheet1!$E:$E,"Yes",Sheet1!$J:$J,$A5,Sheet1!$F:$F,B$2) -> 0 | C5: =COUNTIFS(Sheet1!$E:$E,"Yes",Sheet1!$J:$J,$A5,Sheet1!$F:$F,C$2) -> 7 | D5: =COUNTIFS(Sheet1!$E:$E,"Yes",Sheet1!$J:$J,$A5,Sheet1!$F:$F,D$2) -> 28 | E5: =COUNTIFS(Sheet1!$E:$E,"Yes",Sheet1!$J:$J,$A5,Sheet1!$F:$F,E$2) -> 43 | F5: =SUM(B5:E5) -> 78
A6: General Threat > health | B6: =COUNTIFS(Sheet1!$E:$E,"Yes",Sheet1!$J:$J,$A6,Sheet1!$F:$F,B$2) -> 4 | C6: =COUNTIFS(Sheet1!$E:$E,"Yes",Sheet1!$J:$J,$A6,Sheet1!$F:$F,C$2) -> 62 | D6: =COUNTIFS(Sheet1!$E:$E,"Yes",Sheet1!$J:$J,$A6,Sheet1!$F:$F,D$2) -> 126 | E6: =COUNTIFS(Sheet1!$E:$E,"Yes",Sheet1!$J:$J,$A6,Sheet1!$F:$F,E$2) -> 139 | F6: =SUM(B6:E6) -> 331
A7: Social/Self-worth > moral_identity | B7: =COUNTIFS(Sheet1!$E:$E,"Yes",Sheet1!$J:$J,$A7,Sheet1!$F:$F,B$2) -> 2 | C7: =COUNTIFS(Sheet1!$E:$E,"Yes",Sheet1!$J:$J,$A7,Sheet1!$F:$F,C$2) -> 57 | D7: =COUNTIFS(Sheet1!$E:$E,"Yes",Sheet1!$J:$J,$A7,Sheet1!$F:$F,D$2) -> 63 | E7: =COUNTIFS(Sheet1!$E:$E,"Yes",Sheet1!$J:$J,$A7,Sheet1!$F:$F,E$2) -> 24 | F7: =SUM(B7:E7) -> 146
